root - ERROR - Error occurred while processing brand: Cité with link: https://www.parfumo.com/Perfumes/cité?current_page=1&.
Traceback (most recent call last):
  File "/home/gabriel/projetos/parfumo-scraper/webparfumo/app/controller/perfumes.py", line 66, in connectPerfumePageListId
    PerfumesTags = tree.xpath('//div[@class="pgrid mb-1"]')[0]
IndexError: list index out of range
root - ERROR - Error occurred while processing brand: Hoermanseder with link: https://www.parfumo.com/Perfumes/hoermanseder?current_page=1&.
Traceback (most recent call last):
  File "/home/gabriel/projetos/parfumo-scraper/webparfumo/app/controller/perfumes.py", line 66, in connectPerfumePageListId
    PerfumesTags = tree.xpath('//div[@class="pgrid mb-1"]')[0]
IndexError: list index out of range
root - ERROR - Error occurred while processing brand: Mäurer & Wirtz with link: https://www.parfumo.com/Perfumes/Maeurer_Wirtz?current_page=1&.
Traceback (most recent call last):
  File "/home/gabriel/projetos/parfumo-scraper/webparfumo/app/controller/perfumes.py", line 69, in connectPerfumePageListId
    perfumeName =  perfumeTag.xpath('.//div[@class="name"]/a/text()')[0]
IndexError: list index out of range
root - ERROR - Error occurred while processing brand: Note 33 with link: https://www.parfumo.com/Perfumes/Note_33?current_page=1&.
Traceback (most recent call last):
  File "/home/gabriel/projetos/parfumo-scraper/webparfumo/app/controller/perfumes.py", line 69, in connectPerfumePageListId
    perfumeName =  perfumeTag.xpath('.//div[@class="name"]/a/text()')[0]
IndexError: list index out of range
root - ERROR - Error occurred while processing brand: Pedro del Hierro with link: https://www.parfumo.com/Perfumes/Pedro_del_Hierro?current_page=1&.
Traceback (most recent call last):
  File "/home/gabriel/anaconda3/lib/python3.10/site-packages/urllib3/connectionpool.py", line 703, in urlopen
    httplib_response = self._make_request(
  File "/home/gabriel/anaconda3/lib/python3.10/site-packages/urllib3/connectionpool.py", line 449, in _make_request
    six.raise_from(e, None)
  File "<string>", line 3, in raise_from
  File "/home/gabriel/anaconda3/lib/python3.10/site-packages/urllib3/connectionpool.py", line 444, in _make_request
    httplib_response = conn.getresponse()
  File "/home/gabriel/anaconda3/lib/python3.10/http/client.py", line 1374, in getresponse
    response.begin()
  File "/home/gabriel/anaconda3/lib/python3.10/http/client.py", line 318, in begin
    version, status, reason = self._read_status()
  File "/home/gabriel/anaconda3/lib/python3.10/http/client.py", line 287, in _read_status
    raise RemoteDisconnected("Remote end closed connection without"
http.client.RemoteDisconnected: Remote end closed connection without response

During handling of the above exception, another exception occurred:

Traceback (most recent call last):
  File "/home/gabriel/anaconda3/lib/python3.10/site-packages/requests/adapters.py", line 487, in send
    resp = conn.urlopen(
  File "/home/gabriel/anaconda3/lib/python3.10/site-packages/urllib3/connectionpool.py", line 787, in urlopen
    retries = retries.increment(
  File "/home/gabriel/anaconda3/lib/python3.10/site-packages/urllib3/util/retry.py", line 550, in increment
    raise six.reraise(type(error), error, _stacktrace)
  File "/home/gabriel/anaconda3/lib/python3.10/site-packages/urllib3/packages/six.py", line 769, in reraise
    raise value.with_traceback(tb)
  File "/home/gabriel/anaconda3/lib/python3.10/site-packages/urllib3/connectionpool.py", line 703, in urlopen
    httplib_response = self._make_request(
  File "/home/gabriel/anaconda3/lib/python3.10/site-packages/urllib3/connectionpool.py", line 449, in _make_request
    six.raise_from(e, None)
  File "<string>", line 3, in raise_from
  File "/home/gabriel/anaconda3/lib/python3.10/site-packages/urllib3/connectionpool.py", line 444, in _make_request
    httplib_response = conn.getresponse()
  File "/home/gabriel/anaconda3/lib/python3.10/http/client.py", line 1374, in getresponse
    response.begin()
  File "/home/gabriel/anaconda3/lib/python3.10/http/client.py", line 318, in begin
    version, status, reason = self._read_status()
  File "/home/gabriel/anaconda3/lib/python3.10/http/client.py", line 287, in _read_status
    raise RemoteDisconnected("Remote end closed connection without"
urllib3.exceptions.ProtocolError: ('Connection aborted.', RemoteDisconnected('Remote end closed connection without response'))

During handling of the above exception, another exception occurred:

Traceback (most recent call last):
  File "/home/gabriel/projetos/parfumo-scraper/webparfumo/app/controller/perfumes.py", line 64, in connectPerfumePageListId
    brandPerfumePage = requests.get(url + f'?current_page={page}&', headers=headers)
  File "/home/gabriel/anaconda3/lib/python3.10/site-packages/requests/api.py", line 73, in get
    return request("get", url, params=params, **kwargs)
  File "/home/gabriel/anaconda3/lib/python3.10/site-packages/requests/api.py", line 59, in request
    return session.request(method=method, url=url, **kwargs)
  File "/home/gabriel/anaconda3/lib/python3.10/site-packages/requests/sessions.py", line 587, in request
    resp = self.send(prep, **send_kwargs)
  File "/home/gabriel/anaconda3/lib/python3.10/site-packages/requests/sessions.py", line 701, in send
    r = adapter.send(request, **kwargs)
  File "/home/gabriel/anaconda3/lib/python3.10/site-packages/requests/adapters.py", line 502, in send
    raise ConnectionError(err, request=request)
requests.exceptions.ConnectionError: ('Connection aborted.', RemoteDisconnected('Remote end closed connection without response'))
